Workbook

Sheet User Growth
A1: months | B1: users
A2: 1 | B2: =IF(A2 <= L9, 0, 'User Growth'!L7 / (1 + ('User Growth'!L7 - 'User Growth'!L6) / 'User Growth'!L6 * EXP(-'User Growth'!L8 * A2))) -> 0
A3: 2 | B3: =IF(A3 <= L9, 0, L7 / (1 + (L7 - L6) / L6 * EXP(-L8 * A3))) -> 0
A4: 3 | B4: =IF(A4 <= L9, 0, L7 / (1 + (L7 - L6) / L6 * EXP(-L8 * A4))) -> 0
A5: 4 | B5: =IF(A5 <= L9, 0, L7 / (1 + (L7 - L6) / L6 * EXP(-L8 * A5))) -> 0 | K5: input data.
A6: 5 | B6: =IF(A6 <= L9, 0, L7 / (1 + (L7 - L6) / L6 * EXP(-L8 * A6))) -> 0 | K6: Initial Users | L6: 250
A7: 6 | B7: =IF(A7 <= L9, 0, L7 / (1 + (L7 - L6) / L6 * EXP(-L8 * A7))) -> 0 | K7: Upper Limit | L7: 25000
A8: 7 | B8: =IF(A8 <= L9, 0, L7 / (1 + (L7 - L6) / L6 * EXP(-L8 * A8))) -> 0 | K8: Growth Rate | L8: 0.25
A9: 8 | B9: =IF(A9 <= L9, 0, L7 / (1 + (L7 - L6) / L6 * EXP(-L8 * A9))) -> 0 | K9: Dev Months | L9: 9
A10: 9 | B10: =IF(A10 <= L9, 0, L7 / (1 + (L7 - L6) / L6 * EXP(-L8 * A10))) -> 0
A11: 10 | B11: =IF(A11 <= L9, 0, L7 / (1 + (L7 - L6) / L6 * EXP(-L8 * (A11 - L9)))) -> 320.0972
A12: 11 | B12: =IF(A12 <= L9, 0, L7 / (1 + (L7 - L6) / L6 * EXP(-L8 * (A12 - L9)))) -> 409.52365
A13: 12 | B13: =IF(A13 <= L9, 0, L7 / (1 + (L7 - L6) / L6 * EXP(-L8 * (A13 - L9)))) -> 523.40359
A14: 13 | B14: =IF(A14 <= L9, 0, L7 / (1 + (L7 - L6) / L6 * EXP(-L8 * (A14 - L9)))) -> 668.09077
A15: 14 | B15: =IF(A15 <= L9, 0, L7 / (1 + (L7 - L6) / L6 * EXP(-L8 * (A15 - L9)))) -> 851.38337
A16: 15 | B16: =IF(A16 <= L9, 0, L7 / (1 + (L7 - L6) / L6 * EXP(-L8 * (A16 - L9)))) -> 1082.7251
A17: 16 | B17: =IF(A17 <= L9, 0, L7 / (1 + (L7 - L6) / L6 * EXP(-L8 * (A17 - L9)))) -> 1373.3532
A18: 17 | B18: =IF(A18 <= L9, 0, L7 / (1 + (L7 - L6) / L6 * EXP(-L8 * (A18 - L9)))) -> 1736.329
A19: 18 | B19: =IF(A19 <= L9, 0, L7 / (1 + (L7 - L6) / L6 * EXP(-L8 * (A19 - L9)))) -> 2186.3614
A20: 19 | B20: =IF(A20 <= L9, 0, L7 / (1 + (L7 - L6) / L6 * EXP(-L8 * (A20 - L9)))) -> 2739.3013
A21: 20 | B21: =IF(A21 <= L9, 0, L7 / (1 + (L7 - L6) / L6 * EXP(-L8 * (A21 - L9)))) -> 3411.1725
A22: 21 | B22: =IF(A22 <= L9, 0, L7 / (1 + (L7 - L6) / L6 * EXP(-L8 * (A22 - L9)))) -> 4216.6197
A23: 22 | B23: =IF(A23 <= L9, 0, L7 / (1 + (L7 - L6) / L6 * EXP(-L8 * (A23 - L9)))) -> 5166.734
A24: 23 | B24: =IF(A24 <= L9, 0, L7 / (1 + (L7 - L6) / L6 * EXP(-L8 * (A24 - L9)))) -> 6266.3851
A25: 24 | B25: =IF(A25 <= L9, 0, L7 / (1 + (L7 - L6) / L6 * EXP(-L8 * (A25 - L9)))) -> 7511.4395
A26: 25 | B26: =IF(A26 <= L9, 0, L7 / (1 + (L7 - L6) / L6 * EXP(-L8 * (A26 - L9)))) -> 8886.5247
A27: 26 | B27: =IF(A27 <= L9, 0, L7 / (1 + (L7 - L6) / L6 * EXP(-L8 * (A27 - L9)))) -> 10364.159
A28: 27 | B28: =IF(A28 <= L9, 0, L7 / (1 + (L7 - L6) / L6 * EXP(-L8 * (A28 - L9)))) -> 11905.949
A29: 28 | B29: =IF(A29 <= L9, 0, L7 / (1 + (L7 - L6) / L6 * EXP(-L8 * (A29 - L9)))) -> 13466.071 | K29: upper limit.
A30: 29 | B30: =IF(A30 <= L9, 0, L7 / (1 + (L7 - L6) / L6 * EXP(-L8 * (A30 - L9)))) -> 14996.49 | K30: total serviceable market | L30: 18-30 in uk | N30: 8000000
A31: 30 | B31: =IF(A31 <= L9, 0, L7 / (1 + (L7 - L6) / L6 * EXP(-L8 * (A31 - L9)))) -> 16452.734 | K31: total target market | L31: scared of gym | M31: 0.3 | N31: =N30*M31 -> 2400000
A32: 31 | B32: =IF(A32 <= L9, 0, L7 / (1 + (L7 - L6) / L6 * EXP(-L8 * (A32 - L9)))) -> 17798.784 | K32: 2% of target market | L32: reasonable | M32: 0.02 | N32: =N31*M32 -> 48000
A33: 32 | B33: =IF(A33 <= L9, 0, L7 / (1 + (L7 - L6) / L6 * EXP(-L8 * (A33 - L9)))) -> 19010.029
A34: 33 | B34: =IF(A34 <= L9, 0, L7 / (1 + (L7 - L6) / L6 * EXP(-L8 * (A34 - L9)))) -> 20073.929
A35: 34 | B35: =IF(A35 <= L9, 0, L7 / (1 + (L7 - L6) / L6 * EXP(-L8 * (A35 - L9)))) -> 20988.738 | K35: valuation.
A36: 35 | B36: =IF(A36 <= L9, 0, L7 / (1 + (L7 - L6) / L6 * EXP(-L8 * (A36 - L9)))) -> 21761.072 | K36: ebitda (3rd yr profit) | L36: =Summary!D40 -> 1572998.5
A37: 36 | B37: =IF(A37 <= L9, 0, L7 / (1 + (L7 - L6) / L6 * EXP(-L8 * (A37 - L9)))) -> 22403.098 | K37: valuation ^^ | L37: =L36 * 6 -> 9437990.9
K38: offer (3rd yr profit) | L38: =(L46/L36) -> 0.57215567
K40: ebitda ( month x 12) | L40: ='P&L'!AO35 * 12 -> 2743636.9
K41: valuation ^^ | L41: =L40 * 6 -> 16461821
...

Sheet Assumptions
A1: Company | B1: CONKR.
A2: KEY Assumptions
A4: Average Income Per User/Unit Per Month | C4: 11
A6: Number of users Per Month | B6: Year 1
B7: Month 1 | C7: Month 2 | D7: Month 3 | E7: Month 4 | F7: Month 5 | G7: Month 6 | H7: Month 7 | I7: Month 8 | J7: Month 9 | K7: Month 10 | L7: Month 11 | M7: Month 12 | P7: through initial stages of beta testing, we start with x number of users
A8: Number of users / Units | B8: ='User Growth'!B2 -> 0 | C8: ='User Growth'!B3 -> 0 | D8: ='User Growth'!B4 -> 0 | E8: ='User Growth'!B5 -> 0 | F8: ='User Growth'!B6 -> 0 | G8: ='User Growth'!B7 -> 0 | H8: ='User Growth'!B8 -> 0 | I8: ='User Growth'!B9 -> 0 | J8: ='User Growth'!B10 -> 0 | K8: ='User Growth'!B11 -> 320.0972 | L8: ='User Growth'!B12 -> 409.52365 | M8: ='User Growth'!B13 -> 523.40359
B9: Year 2
B10: Month 13 | C10: Month 14 | D10: Month 15 | E10: Month 16 | F10: Month 17 | G10: Month 18 | H10: Month 19 | I10: Month 20 | J10: Month 21 | K10: Month 22 | L10: Month 23 | M10: Month 24
A11: Number of users | B11: ='User Growth'!B14 -> 668.09077 | C11: ='User Growth'!B15 -> 851.38337 | D11: ='User Growth'!B16 -> 1082.7251 | E11: ='User Growth'!B17 -> 1373.3532 | F11: ='User Growth'!B18 -> 1736.329 | G11: ='User Growth'!B19 -> 2186.3614 | H11: ='User Growth'!B20 -> 2739.3013 | I11: ='User Growth'!B21 -> 3411.1725 | J11: ='User Growth'!B22 -> 4216.6197 | K11: ='User Growth'!B23 -> 5166.734 | L11: ='User Growth'!B24 -> 6266.3851 | M11: ='User Growth'!B25 -> 7511.4395
B12: Year 3
B13: Month 25 | C13: Month 26 | D13: Month 27 | E13: Month 28 | F13: Month 29 | G13: Month 30 | H13: Month 31 | I13: Month 32 | J13: Month 33 | K13: Month 34 | L13: Month 35 | M13: Month 36
A14: Number of users | B14: ='User Growth'!B26 -> 8886.5247 | C14: ='User Growth'!B27 -> 10364.159 | D14: ='User Growth'!B28 -> 11905.949 | E14: ='User Growth'!B29 -> 13466.071 | F14: ='User Growth'!B30 -> 14996.49 | G14: ='User Growth'!B31 -> 16452.734 | H14: ='User Growth'!B32 -> 17798.784 | I14: ='User Growth'!B33 -> 19010.029 | J14: ='User Growth'!B34 -> 20073.929 | K14: ='User Growth'!B35 -> 20988.738 | L14: ='User Growth'!B36 -> 21761.072 | M14: ='User Growth'!B37 -> 22403.098
A16: Cost of Sales | B16: Yr1 | C16: Yr2 | D16: Yr3
A17: % of user sales | B17: 0.01 | C17: 0.01 | D17: 0.01
A19: Expenses | B19: Year 1 | C19: Year 2 | D19: Year 3
A20: CEO | B20: 20000 | C20: 25000 | D20: 40000
A21: Administration | B21: 0 | C21: 5000 | D21: 5000
A22: Other Staff Costs | B22: 40000 | C22: 50000 | D22: 60000
A23: Motor & travel expenses | B23: 0 | C23: 0 | D23: 0
A24: Materials/Resources | B24: 0 | C24: 0 | D24: 0
A25: Marketing | B25: 20000 | C25: 30000 | D25: 30000
A26: Insurance | B26: 14000 | C26: 14000 | D26: 14000
A27: Computer & IT costs | B27: 1000 | C27: 1000 | D27: 1000
A28: Office Rent & services | B28: 0 | C28: 0 | D28: 0
A29: Telephone | B29: 0 | C29: 0 | D29: 0
A31: Investment Received | B31: Month 1 | C31: Month 2 | D31: Month 3 | E31: Month 4 | F31: Month 5 | G31: Month 6 | H31: Month 7 | I31: Month 8 | J31: Month 9 | K31: Month 10 | L31: Month 11 | M31: Month 12
A32: Founder | B32: 15000
A33: Investment | B33: 150000 | G33: 0
B34: Month 13 | C34: Month 14 | D34: Month 15 | E34: Month 16 | F34: Month 17 | G34: Month 18 | H34: Month 19 | I34: Month 20 | J34: Month 21 | K34: Month 22 | L34: Month 23 | M34: Month 24
A35: Founder
A36: Investment | B36: 0
B37: Month 25 | C37: Month 26 | D37: Month 27 | E37: Month 28 | F37: Month 29 | G37: Month 30 | H37: Month 31 | I37: Month 32 | J37: Month 33 | K37: Month 34 | L37: Month 35 | M37: Month 36
A38: Founder
A39: Investment
A41: Fund raising costs | B41: 0.05
A43: Development Expenditure | B43: Year 1
B44: Month 1 | C44: Month 2 | D44: Month 3 | E44: Month 4 | F44: Month 5 | G44: Month 6 | H44: Month 7 | I44: Month 8 | J44: Month 9 | K44: Month 10 | L44: Month 11 | M44: Month 12
A45: Development Expenditure | B45: 5000 | C45: 5000 | D45: 5000 | E45: 5000 | F45: 5000 | G45: 5000 | H45: 5000 | I45: 5000 | J45: 5000 | K45: 5000 | L45: 5000 | M45: 5000
B46: Year 2
B47: Month 13 | C47: Month 14 | D47: Month 15 | E47: Month 16 | F47: Month 17 | G47: Month 18 | H47: Month 19 | I47: Month 20 | J47: Month 21 | K47: Month 22 | L47: Month 23 | M47: Month 24
...

Sheet Summary
A1: =Assumptions!B1 -> CONKR.
A3: ='P&L'!A2 -> Profit and Loss forecast | B3: Yr 1 | C3: Yr 2 | D3: Yr 3
B4: £ | C4: £ | D4: £
A6: Turnover
A7: ='P&L'!A6 -> User income | B7: ='P&L'!N6 -> 13783.269 | C7: ='P&L'!AB6 -> 409308.85 | D7: ='P&L'!AP6 -> 2179183.3
A9: ='P&L'!A8 -> Total | B9: ='P&L'!N8 -> 13783.269 | C9: ='P&L'!AB8 -> 409308.85 | D9: ='P&L'!AP8 -> 2179183.3
A11: Cost of Sales
A12: ='P&L'!A11 -> Direct Selling costs | B12: ='P&L'!N11 -> 137.83269 | C12: ='P&L'!AB11 -> 4093.0885 | D12: ='P&L'!AP11 -> 21791.833
A14: Gross Profit | B14: =B9-B12 -> 13645.436 | C14: =C9-C12 -> 405215.76 | D14: =D9-D12 -> 2157391.5
A17: Overheads
A18: ='P&L'!A17 -> CEO | B18: ='P&L'!N17 -> 20000 | C18: ='P&L'!AB17 -> 25000 | D18: ='P&L'!AP17 -> 40000
A19: ='P&L'!A18 -> Administration | B19: ='P&L'!N18 -> 0 | C19: ='P&L'!AB18 -> 5000 | D19: ='P&L'!AP18 -> 5000
A20: ='P&L'!A19 -> Other Staff Costs | B20: ='P&L'!N19 -> 40000 | C20: ='P&L'!AB19 -> 50000 | D20: ='P&L'!AP19 -> 60000
A21: ='P&L'!A20 -> Development Expenditure | B21: ='P&L'!N20 -> 60000 | C21: ='P&L'!AB20 -> 13000 | D21: ='P&L'!AP20 -> 30000
A22: ='P&L'!A21 -> Motor & travel expenses | B22: ='P&L'!N21 -> 0 | C22: ='P&L'!AB21 -> 0 | D22: ='P&L'!AP21 -> 0
A23: ='P&L'!A22 -> Materials/Resources | B23: ='P&L'!N22 -> 0 | C23: ='P&L'!AB22 -> 0 | D23: ='P&L'!AP22 -> 0
A24: ='P&L'!A23 -> Marketing | B24: ='P&L'!N23 -> 20000 | C24: ='P&L'!AB23 -> 30000 | D24: ='P&L'!AP23 -> 30000
A25: ='P&L'!A24 -> Insurance | B25: ='P&L'!N24 -> 14000 | C25: ='P&L'!AB24 -> 14000 | D25: ='P&L'!AP24 -> 14000
A26: ='P&L'!A25 -> Computer & IT costs | B26: ='P&L'!N25 -> 1000 | C26: ='P&L'!AB25 -> 1000 | D26: ='P&L'!AP25 -> 1000
A27: ='P&L'!A26 -> Office Rent & services | B27: ='P&L'!N26 -> 0 | C27: ='P&L'!AB26 -> 0 | D27: ='P&L'!AP26 -> 0
A28: ='P&L'!A27 -> Telephone | B28: ='P&L'!N27 -> 0 | C28: ='P&L'!AB27 -> 0 | D28: ='P&L'!AP27 -> 0
A29: ='P&L'!A28 -> Fund raising costs | B29: ='P&L'!N28 -> 7500 | C29: ='P&L'!AB28 -> 0 | D29: ='P&L'!AP28 -> 0
... A31: ='P&L'!A30 -> Depreciation | B31: ='P&L'!N30 -> 0 | C31: ='P&L'!AB30 -> 0 | D31: ='P&L'!AP30 -> 0
A34: ='P&L'!A32 -> Total | B34: =SUM(B18:B33) -> 162500 | C34: =SUM(C18:C33) -> 148000 | D34: =SUM(D18:D33) -> 190000
A36: ='P&L'!A35 -> Profit (loss) before tax | B36: =B14-B34 -> -148854.56 | C36: =C14-C34 -> 257215.76 | D36: =D14-D34 -> 1967391.5
A38: ='P&L'!A37 -> Tax | B38: ='P&L'!N37 -> 0 | C38: ='P&L'!AB37 -> 20588.627 | D38: ='P&L'!AP37 -> -394393.01
A40: ='P&L'!A39 -> Retained profit | B40: ='P&L'!N39 -> -148854.56 | C40: ='P&L'!AB39 -> 277804.38 | D40: ='P&L'!AP39 -> 1572998.5
A43: =A1 -> CONKR.
A45: Financial summary
A47: Cash Flow | B47: Yr 1 | C47: Yr 2 | D47: Yr 3
B48: £ | C48: £ | D48: £
A49: =Cashflow!A5 -> Income
A50: =Cashflow!A6 -> Founder | B50: =Cashflow!N6 -> 15000 | C50: =Cashflow!AB6 -> 0 | D50: =Cashflow!AP6 -> 0
A51: =Cashflow!A7 -> Investment | B51: =Cashflow!N7 -> 150000 | C51: =Cashflow!AB7 -> 0 | D51: =Cashflow!AP7 -> 0
A52: =A7 -> User income | B52: =Cashflow!N8 -> 16539.923 | C52: =Cashflow!AB8 -> 491170.61 | D52: =Cashflow!AP8 -> 2615020
A53: =Cashflow!A9 -> VAT Recovered | B53: =Cashflow!N9 -> 15750 | C53: =Cashflow!AB9 -> 2020.9128 | D53: =Cashflow!AP9
A55: =Cashflow!A11 -> Total | B55: =Cashflow!N11 -> 197289.92 | C55: =Cashflow!AB11 -> 493191.53 | D55: =Cashflow!AP11 -> 2615020
A57: Expenditure
A59: =Cashflow!A14 -> Direct Selling costs | B59: =Cashflow!N14 -> 165.39923 | C59: =Cashflow!AB14 -> 4911.7061 | D59: =Cashflow!AP14 -> 26150.2
A60: =Cashflow!A15 -> CEO | B60: =Cashflow!N15 -> 16000 | C60: =Cashflow!AB15 -> 20000 | D60: =Cashflow!AP15 -> 32000
...

Sheet P&L
A1: =Assumptions!B1 -> CONKR.
A2: Profit and Loss forecast
B4: Month 1 | C4: Month 2 | D4: Month 3 | E4: Month 4 | F4: Month 5 | G4: Month 6 | H4: Month 7 | I4: Month 8 | J4: Month 9 | K4: Month 10 | L4: Month 11 | M4: Month 12 | N4: Total | P4: Month 13 | Q4: Month 14 | R4: Month 15 | S4: Month 16 | T4: Month 17 | U4: Month 18 | V4: Month 19 | W4: Month 20 | X4: Month 21 | Y4: Month 22 | Z4: Month 23 | AA4: Month 24 | AB4: Total | AD4: Month 25 | AE4: Month 26 | AF4: Month 27 | AG4: Month 28 | AH4: Month 29 | AI4: Month 30 | AJ4: Month 31 | AK4: Month 32 | AL4: Month 33 | AM4: Month 34 | AN4: Month 35 | AO4: Month 36 | AP4: Total
A5: Income
A6: User income | B6: =Assumptions!B8*Assumptions!$C$4 -> 0 | C6: =Assumptions!C8*Assumptions!$C$4 -> 0 | D6: =Assumptions!D8*Assumptions!$C$4 -> 0 | E6: =Assumptions!E8*Assumptions!$C$4 -> 0 | F6: =Assumptions!F8*Assumptions!$C$4 -> 0 | G6: =Assumptions!G8*Assumptions!$C$4 -> 0 | H6: =Assumptions!H8*Assumptions!$C$4 -> 0 | I6: =Assumptions!I8*Assumptions!$C$4 -> 0 | ... M6: =Assumptions!M8*Assumptions!$C$4 -> 5757.4394 | N6: =SUM(B6:M6) -> 13783.269 | P6: =Assumptions!B11*Assumptions!$C$4 -> 7348.9985 | Q6: =Assumptions!C11*Assumptions!$C$4 -> 9365.2171 | R6: =Assumptions!D11*Assumptions!$C$4 -> 11909.977 | S6: =Assumptions!E11*Assumptions!$C$4 -> 15106.885 | T6: =Assumptions!F11*Assumptions!$C$4 -> 19099.619 | U6: =Assumptions!G11*Assumptions!$C$4 -> 24049.975 | V6: =Assumptions!H11*Assumptions!$C$4 -> 30132.314 | W6: =Assumptions!I11*Assumptions!$C$4 -> 37522.898 | ... AA6: =Assumptions!M11*Assumptions!$C$4 -> 82625.835 | AB6: =SUM(P6:AA6) -> 409308.85 | AD6: =Assumptions!B14*Assumptions!$C$4 -> 97751.771 | AE6: =Assumptions!C14*Assumptions!$C$4 -> 114005.74 | AF6: =Assumptions!D14*Assumptions!$C$4 -> 130965.44 | AG6: =Assumptions!E14*Assumptions!$C$4 -> 148126.78 | AH6: =Assumptions!F14*Assumptions!$C$4 -> 164961.39 | AI6: =Assumptions!G14*Assumptions!$C$4 -> 180980.07 | AJ6: =Assumptions!H14*Assumptions!$C$4 -> 195786.62 | AK6: =Assumptions!I14*Assumptions!$C$4 -> 209110.32 | ... AO6: =Assumptions!M14*Assumptions!$C$4 -> 246434.08 | AP6: =SUM(AD6:AO6) -> 2179183.3
A8: Total | B8: =SUM(B6) -> 0 | C8: =SUM(C6) -> 0 | D8: =SUM(D6) -> 0 | E8: =SUM(E6) -> 0 | F8: =SUM(F6) -> 0 | G8: =SUM(G6) -> 0 | H8: =SUM(H6) -> 0 | I8: =SUM(I6) -> 0 | ... M8: =SUM(M6) -> 5757.4394 | N8: =SUM(B8:M8) -> 13783.269 | P8: =SUM(P6) -> 7348.9985 | Q8: =SUM(Q6) -> 9365.2171 | R8: =SUM(R6) -> 11909.977 | S8: =SUM(S6) -> 15106.885 | T8: =SUM(T6) -> 19099.619 | U8: =SUM(U6) -> 24049.975 | V8: =SUM(V6) -> 30132.314 | W8: =SUM(W6) -> 37522.898 | ... AB8: =SUM(AB6) -> 409308.85 | AD8: =SUM(AD6) -> 97751.771 | AE8: =SUM(AE6) -> 114005.74 | AF8: =SUM(AF6) -> 130965.44 | AG8: =SUM(AG6) -> 148126.78 | AH8: =SUM(AH6) -> 164961.39 | AI8: =SUM(AI6) -> 180980.07 | AJ8: =SUM(AJ6) -> 195786.62 | AK8: =SUM(AK6) -> 209110.32 | ... AP8: =SUM(AP6) -> 2179183.3
A10: Cost of Sales
A11: Direct Selling costs | B11: =Assumptions!$B17*'P&L'!B6 -> 0 | C11: =Assumptions!$B17*'P&L'!C6 -> 0 | D11: =Assumptions!$B17*'P&L'!D6 -> 0 | E11: =Assumptions!$B17*'P&L'!E6 -> 0 | F11: =Assumptions!$B17*'P&L'!F6 -> 0 | G11: =Assumptions!$B17*'P&L'!G6 -> 0 | H11: =Assumptions!$B17*'P&L'!H6 -> 0 | I11: =Assumptions!$B17*'P&L'!I6 -> 0 | ... N11: =Assumptions!$B17*'P&L'!N6 -> 137.83269 | P11: =Assumptions!$C17*'P&L'!P6 -> 73.489985 | Q11: =Assumptions!$C17*'P&L'!Q6 -> 93.652171 | R11: =Assumptions!$C17*'P&L'!R6 -> 119.09977 | S11: =Assumptions!$C17*'P&L'!S6 -> 151.06885 | T11: =Assumptions!$C17*'P&L'!T6 -> 190.99619 | U11: =Assumptions!$C17*'P&L'!U6 -> 240.49975 | V11: =Assumptions!$C17*'P&L'!V6 -> 301.32314 | W11: =Assumptions!$C17*'P&L'!W6 -> 375.22898 | ... AB11: =Assumptions!$C17*'P&L'!AB6 -> 4093.0885 | AD11: =Assumptions!$D17*'P&L'!AD6 -> 977.51771 | AE11: =Assumptions!$D17*'P&L'!AE6 -> 1140.0574 | AF11: =Assumptions!$D17*'P&L'!AF6 -> 1309.6544 | AG11: =Assumptions!$D17*'P&L'!AG6 -> 1481.2678 | AH11: =Assumptions!$D17*'P&L'!AH6 -> 1649.6139 | AI11: =Assumptions!$D17*'P&L'!AI6 -> 1809.8007 | AJ11: =Assumptions!$D17*'P&L'!AJ6 -> 1957.8662 | AK11: =Assumptions!$D17*'P&L'!AK6 -> 2091.1032 | ... AP11: =Assumptions!$D17*'P&L'!AP6 -> 21791.833
A13: Gross Profit | B13: =B8-B11 -> 0 | C13: =C8-C11 -> 0 | D13: =D8-D11 -> 0 | E13: =E8-E11 -> 0 | F13: =F8-F11 -> 0 | G13: =G8-G11 -> 0 | H13: =H8-H11 -> 0 | I13: =I8-I11 -> 0 | ... N13: =N8-N11 -> 13645.436 | P13: =P8-P11 -> 7275.5085 | Q13: =Q8-Q11 -> 9271.5649 | R13: =R8-R11 -> 11790.877 | S13: =S8-S11 -> 14955.816 | T13: =T8-T11 -> 18908.623 | U13: =U8-U11 -> 23809.475 | V13: =V8-V11 -> 29830.991 | W13: =W8-W11 -> 37147.669 | ... AB13: =AB8-AB11 -> 405215.76 | AD13: =AD8-AD11 -> 96774.254 | AE13: =AE8-AE11 -> 112865.69 | AF13: =AF8-AF11 -> 129655.78 | AG13: =AG8-AG11 -> 146645.51 | AH13: =AH8-AH11 -> 163311.78 | AI13: =AI8-AI11 -> 179170.27 | AJ13: =AJ8-AJ11 -> 193828.75 | AK13: =AK8-AK11 -> 207019.22 | ... AP13: =AP8-AP11 -> 2157391.5
A16: Expenses
A17: =Assumptions!A20 -> CEO | B17: =Assumptions!$B20/12 -> 1666.6667 | C17: =Assumptions!$B20/12 -> 1666.6667 | D17: =Assumptions!$B20/12 -> 1666.6667 | E17: =Assumptions!$B20/12 -> 1666.6667 | F17: =Assumptions!$B20/12 -> 1666.6667 | G17: =Assumptions!$B20/12 -> 1666.6667 | H17: =Assumptions!$B20/12 -> 1666.6667 | I17: =Assumptions!$B20/12 -> 1666.6667 | ... M17: =Assumptions!$B20/12 -> 1666.6667 | N17: =SUM(B17:M17) -> 20000 | P17: =Assumptions!$C20/12 -> 2083.3333 | Q17: =Assumptions!$C20/12 -> 2083.3333 | R17: =Assumptions!$C20/12 -> 2083.3333 | S17: =Assumptions!$C20/12 -> 2083.3333 | T17: =Assumptions!$C20/12 -> 2083.3333 | U17: =Assumptions!$C20/12 -> 2083.3333 | V17: =Assumptions!$C20/12 -> 2083.3333 | W17: =Assumptions!$C20/12 -> 2083.3333 | ... AA17: =Assumptions!$C20/12 -> 2083.3333 | AB17: =SUM(P17:AA17) -> 25000 | AD17: =Assumptions!$D20/12 -> 3333.3333 | AE17: =Assumptions!$D20/12 -> 3333.3333 | AF17: =Assumptions!$D20/12 -> 3333.3333 | AG17: =Assumptions!$D20/12 -> 3333.3333 | AH17: =Assumptions!$D20/12 -> 3333.3333 | AI17: =Assumptions!$D20/12 -> 3333.3333 | AJ17: =Assumptions!$D20/12 -> 3333.3333 | AK17: =Assumptions!$D20/12 -> 3333.3333 | ... AO17: =Assumptions!$D20/12 -> 3333.3333 | AP17: =SUM(AD17:AO17) -> 40000
A18: =Assumptions!A21 -> Administration | B18: =Assumptions!$B21/12 -> 0 | C18: =Assumptions!$B21/12 -> 0 | D18: =Assumptions!$B21/12 -> 0 | E18: =Assumptions!$B21/12 -> 0 | F18: =Assumptions!$B21/12 -> 0 | G18: =Assumptions!$B21/12 -> 0 | H18: =Assumptions!$B21/12 -> 0 | I18: =Assumptions!$B21/12 -> 0 | ... M18: =Assumptions!$B21/12 -> 0 | N18: =SUM(B18:M18) -> 0 | P18: =Assumptions!$C21/12 -> 416.66667 | Q18: =Assumptions!$C21/12 -> 416.66667 | R18: =Assumptions!$C21/12 -> 416.66667 | S18: =Assumptions!$C21/12 -> 416.66667 | T18: =Assumptions!$C21/12 -> 416.66667 | U18: =Assumptions!$C21/12 -> 416.66667 | V18: =Assumptions!$C21/12 -> 416.66667 | W18: =Assumptions!$C21/12 -> 416.66667 | ... AA18: =Assumptions!$C21/12 -> 416.66667 | AB18: =SUM(P18:AA18) -> 5000 | AD18: =Assumptions!$D21/12 -> 416.66667 | AE18: =Assumptions!$D21/12 -> 416.66667 | AF18: =Assumptions!$D21/12 -> 416.66667 | AG18: =Assumptions!$D21/12 -> 416.66667 | AH18: =Assumptions!$D21/12 -> 416.66667 | AI18: =Assumptions!$D21/12 -> 416.66667 | AJ18: =Assumptions!$D21/12 -> 416.66667 | AK18: =Assumptions!$D21/12 -> 416.66667 | ... AO18: =Assumptions!$D21/12 -> 416.66667 | AP18: =SUM(AD18:AO18) -> 5000
A19: =Assumptions!A22 -> Other Staff Costs | B19: =Assumptions!$B22/12 -> 3333.3333 | C19: =Assumptions!$B22/12 -> 3333.3333 | D19: =Assumptions!$B22/12 -> 3333.3333 | E19: =Assumptions!$B22/12 -> 3333.3333 | F19: =Assumptions!$B22/12 -> 3333.3333 | G19: =Assumptions!$B22/12 -> 3333.3333 | H19: =Assumptions!$B22/12 -> 3333.3333 | I19: =Assumptions!$B22/12 -> 3333.3333 | ... M19: =Assumptions!$B22/12 -> 3333.3333 | N19: =SUM(B19:M19) -> 40000 | P19: =Assumptions!$C22/12 -> 4166.6667 | Q19: =Assumptions!$C22/12 -> 4166.6667 | R19: =Assumptions!$C22/12 -> 4166.6667 | S19: =Assumptions!$C22/12 -> 4166.6667 | T19: =Assumptions!$C22/12 -> 4166.6667 | U19: =Assumptions!$C22/12 -> 4166.6667 | V19: =Assumptions!$C22/12 -> 4166.6667 | W19: =Assumptions!$C22/12 -> 4166.6667 | ... AA19: =Assumptions!$C22/12 -> 4166.6667 | AB19: =SUM(P19:AA19) -> 50000 | AD19: =Assumptions!$D22/12 -> 5000 | AE19: =Assumptions!$D22/12 -> 5000 | AF19: =Assumptions!$D22/12 -> 5000 | AG19: =Assumptions!$D22/12 -> 5000 | AH19: =Assumptions!$D22/12 -> 5000 | AI19: =Assumptions!$D22/12 -> 5000 | AJ19: =Assumptions!$D22/12 -> 5000 | AK19: =Assumptions!$D22/12 -> 5000 | ... AO19: =Assumptions!$D22/12 -> 5000 | AP19: =SUM(AD19:AO19) -> 60000
A20: =Assumptions!A43 -> Development Expenditure | B20: =Assumptions!B45 -> 5000 | C20: =Assumptions!C45 -> 5000 | D20: =Assumptions!D45 -> 5000 | E20: =Assumptions!E45 -> 5000 | F20: =Assumptions!F45 -> 5000 | G20: =Assumptions!G45 -> 5000 | H20: =Assumptions!H45 -> 5000 | I20: =Assumptions!I45 -> 5000 | ... M20: =Assumptions!M45 -> 5000 | N20: =SUM(B20:M20) -> 60000 | P20: =Assumptions!B48 -> 2000 | Q20: =Assumptions!C48 -> 0 | R20: =Assumptions!D48 -> 0 | S20: =Assumptions!E48 -> 2000 | T20: =Assumptions!F48 -> 1000 | U20: =Assumptions!G48 -> 1000 | V20: =Assumptions!H48 -> 2000 | W20: =Assumptions!I48 -> 1000 | ... AA20: =Assumptions!M48 -> 1000 | AB20: =SUM(P20:AA20) -> 13000 | AD20: =Assumptions!B51 -> 4000 | AE20: =Assumptions!C51 -> 2000 | AF20: =Assumptions!D51 -> 2000 | AG20: =Assumptions!E51 -> 2000 | AH20: =Assumptions!F51 -> 4000 | AI20: =Assumptions!G51 -> 2000 | AJ20: =Assumptions!H51 -> 2000 | AK20: =Assumptions!I51 -> 2000 | ... AO20: =Assumptions!M51 -> 2000 | AP20: =SUM(AD20:AO20) -> 30000
A21: =Assumptions!A23 -> Motor & travel expenses | B21: =Assumptions!$B23/12 -> 0 | C21: =Assumptions!$B23/12 -> 0 | D21: =Assumptions!$B23/12 -> 0 | E21: =Assumptions!$B23/12 -> 0 | F21: =Assumptions!$B23/12 -> 0 | G21: =Assumptions!$B23/12 -> 0 | H21: =Assumptions!$B23/12 -> 0 | I21: =Assumptions!$B23/12 -> 0 | ... M21: =Assumptions!$B23/12 -> 0 | N21: =SUM(B21:M21) -> 0 | P21: =Assumptions!$C23/12 -> 0 | Q21: =Assumptions!$C23/12 -> 0 | R21: =Assumptions!$C23/12 -> 0 | S21: =Assumptions!$C23/12 -> 0 | T21: =Assumptions!$C23/12 -> 0 | U21: =Assumptions!$C23/12 -> 0 | V21: =Assumptions!$C23/12 -> 0 | W21: =Assumptions!$C23/12 -> 0 | ... AA21: =Assumptions!$C23/12 -> 0 | AB21: =SUM(P21:AA21) -> 0 | AD21: =Assumptions!$D23/12 -> 0 | AE21: =Assumptions!$D23/12 -> 0 | AF21: =Assumptions!$D23/12 -> 0 | AG21: =Assumptions!$D23/12 -> 0 | AH21: =Assumptions!$D23/12 -> 0 | AI21: =Assumptions!$D23/12 -> 0 | AJ21: =Assumptions!$D23/12 -> 0 | AK21: =Assumptions!$D23/12 -> 0 | ... AO21: =Assumptions!$D23/12 -> 0 | AP21: =SUM(AD21:AO21) -> 0
A22: =Assumptions!A24 -> Materials/Resources | B22: =Assumptions!$B24/12 -> 0 | C22: =Assumptions!$B24/12 -> 0 | D22: =Assumptions!$B24/12 -> 0 | E22: =Assumptions!$B24/12 -> 0 | F22: =Assumptions!$B24/12 -> 0 | G22: =Assumptions!$B24/12 -> 0 | H22: =Assumptions!$B24/12 -> 0 | I22: =Assumptions!$B24/12 -> 0 | ... M22: =Assumptions!$B24/12 -> 0 | N22: =SUM(B22:M22) -> 0 | P22: =Assumptions!$C24/12 -> 0 | Q22: =Assumptions!$C24/12 -> 0 | R22: =Assumptions!$C24/12 -> 0 | S22: =Assumptions!$C24/12 -> 0 | T22: =Assumptions!$C24/12 -> 0 | U22: =Assumptions!$C24/12 -> 0 | V22: =Assumptions!$C24/12 -> 0 | W22: =Assumptions!$C24/12 -> 0 | ... AA22: =Assumptions!$C24/12 -> 0 | AB22: =SUM(P22:AA22) -> 0 | AD22: =Assumptions!$D24/12 -> 0 | AE22: =Assumptions!$D24/12 -> 0 | AF22: =Assumptions!$D24/12 -> 0 | AG22: =Assumptions!$D24/12 -> 0 | AH22: =Assumptions!$D24/12 -> 0 | AI22: =Assumptions!$D24/12 -> 0 | AJ22: =Assumptions!$D24/12 -> 0 | AK22: =Assumptions!$D24/12 -> 0 | ... AO22: =Assumptions!$D24/12 -> 0 | AP22: =SUM(AD22:AO22) -> 0
A23: =Assumptions!A25 -> Marketing | B23: =Assumptions!$B25/12 -> 1666.6667 | C23: =Assumptions!$B25/12 -> 1666.6667 | D23: =Assumptions!$B25/12 -> 1666.6667 | E23: =Assumptions!$B25/12 -> 1666.6667 | F23: =Assumptions!$B25/12 -> 1666.6667 | G23: =Assumptions!$B25/12 -> 1666.6667 | H23: =Assumptions!$B25/12 -> 1666.6667 | I23: =Assumptions!$B25/12 -> 1666.6667 | ... M23: =Assumptions!$B25/12 -> 1666.6667 | N23: =SUM(B23:M23) -> 20000 | P23: =Assumptions!$C25/12 -> 2500 | Q23: =Assumptions!$C25/12 -> 2500 | R23: =Assumptions!$C25/12 -> 2500 | S23: =Assumptions!$C25/12 -> 2500 | T23: =Assumptions!$C25/12 -> 2500 | U23: =Assumptions!$C25/12 -> 2500 | V23: =Assumptions!$C25/12 -> 2500 | W23: =Assumptions!$C25/12 -> 2500 | ... AA23: =Assumptions!$C25/12 -> 2500 | AB23: =SUM(P23:AA23) -> 30000 | AD23: =Assumptions!$D25/12 -> 2500 | AE23: =Assumptions!$D25/12 -> 2500 | AF23: =Assumptions!$D25/12 -> 2500 | AG23: =Assumptions!$D25/12 -> 2500 | AH23: =Assumptions!$D25/12 -> 2500 | AI23: =Assumptions!$D25/12 -> 2500 | AJ23: =Assumptions!$D25/12 -> 2500 | AK23: =Assumptions!$D25/12 -> 2500 | ... AO23: =Assumptions!$D25/12 -> 2500 | AP23: =SUM(AD23:AO23) -> 30000
A24: =Assumptions!A26 -> Insurance | B24: =Assumptions!$B26/12 -> 1166.6667 | C24: =Assumptions!$B26/12 -> 1166.6667 | D24: =Assumptions!$B26/12 -> 1166.6667 | E24: =Assumptions!$B26/12 -> 1166.6667 | F24: =Assumptions!$B26/12 -> 1166.6667 | G24: =Assumptions!$B26/12 -> 1166.6667 | H24: =Assumptions!$B26/12 -> 1166.6667 | I24: =Assumptions!$B26/12 -> 1166.6667 | ... M24: =Assumptions!$B26/12 -> 1166.6667 | N24: =SUM(B24:M24) -> 14000 | P24: =Assumptions!$C26/12 -> 1166.6667 | Q24: =Assumptions!$C26/12 -> 1166.6667 | R24: =Assumptions!$C26/12 -> 1166.6667 | S24: =Assumptions!$C26/12 -> 1166.6667 | T24: =Assumptions!$C26/12 -> 1166.6667 | U24: =Assumptions!$C26/12 -> 1166.6667 | V24: =Assumptions!$C26/12 -> 1166.6667 | W24: =Assumptions!$C26/12 -> 1166.6667 | ... AA24: =Assumptions!$C26/12 -> 1166.6667 | AB24: =SUM(P24:AA24) -> 14000 | AD24: =Assumptions!$D26/12 -> 1166.6667 | AE24: =Assumptions!$D26/12 -> 1166.6667 | AF24: =Assumptions!$D26/12 -> 1166.6667 | AG24: =Assumptions!$D26/12 -> 1166.6667 | AH24: =Assumptions!$D26/12 -> 1166.6667 | AI24: =Assumptions!$D26/12 -> 1166.6667 | AJ24: =Assumptions!$D26/12 -> 1166.6667 | AK24: =Assumptions!$D26/12 -> 1166.6667 | ... AO24: =Assumptions!$D26/12 -> 1166.6667 | AP24: =SUM(AD24:AO24) -> 14000
A25: =Assumptions!A27 -> Computer & IT costs | B25: =Assumptions!$B27/12 -> 83.333333 | C25: =Assumptions!$B27/12 -> 83.333333 | D25: =Assumptions!$B27/12 -> 83.333333 | E25: =Assumptions!$B27/12 -> 83.333333 | F25: =Assumptions!$B27/12 -> 83.333333 | G25: =Assumptions!$B27/12 -> 83.333333 | H25: =Assumptions!$B27/12 -> 83.333333 | I25: =Assumptions!$B27/12 -> 83.333333 | ... M25: =Assumptions!$B27/12 -> 83.333333 | N25: =SUM(B25:M25) -> 1000 | P25: =Assumptions!$C27/12 -> 83.333333 | Q25: =Assumptions!$C27/12 -> 83.333333 | R25: =Assumptions!$C27/12 -> 83.333333 | S25: =Assumptions!$C27/12 -> 83.333333 | T25: =Assumptions!$C27/12 -> 83.333333 | U25: =Assumptions!$C27/12 -> 83.333333 | V25: =Assumptions!$C27/12 -> 83.333333 | W25: =Assumptions!$C27/12 -> 83.333333 | ... AA25: =Assumptions!$C27/12 -> 83.333333 | AB25: =SUM(P25:AA25) -> 1000 | AD25: =Assumptions!$D27/12 -> 83.333333 | AE25: =Assumptions!$D27/12 -> 83.333333 | AF25: =Assumptions!$D27/12 -> 83.333333 | AG25: =Assumptions!$D27/12 -> 83.333333 | AH25: =Assumptions!$D27/12 -> 83.333333 | AI25: =Assumptions!$D27/12 -> 83.333333 | AJ25: =Assumptions!$D27/12 -> 83.333333 | AK25: =Assumptions!$D27/12 -> 83.333333 | ... AO25: =Assumptions!$D27/12 -> 83.333333 | AP25: =SUM(AD25:AO25) -> 1000
A26: =Assumptions!A28 -> Office Rent & services | B26: =Assumptions!$B28/12 -> 0 | C26: =Assumptions!$B28/12 -> 0 | D26: =Assumptions!$B28/12 -> 0 | E26: =Assumptions!$B28/12 -> 0 | F26: =Assumptions!$B28/12 -> 0 | G26: =Assumptions!$B28/12 -> 0 | H26: =Assumptions!$B28/12 -> 0 | I26: =Assumptions!$B28/12 -> 0 | ... M26: =Assumptions!$B28/12 -> 0 | N26: =SUM(B26:M26) -> 0 | P26: =Assumptions!$C28/12 -> 0 | Q26: =Assumptions!$C28/12 -> 0 | R26: =Assumptions!$C28/12 -> 0 | S26: =Assumptions!$C28/12 -> 0 | T26: =Assumptions!$C28/12 -> 0 | U26: =Assumptions!$C28/12 -> 0 | V26: =Assumptions!$C28/12 -> 0 | W26: =Assumptions!$C28/12 -> 0 | ... AA26: =Assumptions!$C28/12 -> 0 | AB26: =SUM(P26:AA26) -> 0 | AD26: =Assumptions!$D28/12 -> 0 | AE26: =Assumptions!$D28/12 -> 0 | AF26: =Assumptions!$D28/12 -> 0 | AG26: =Assumptions!$D28/12 -> 0 | AH26: =Assumptions!$D28/12 -> 0 | AI26: =Assumptions!$D28/12 -> 0 | AJ26: =Assumptions!$D28/12 -> 0 | AK26: =Assumptions!$D28/12 -> 0 | ... AO26: =Assumptions!$D28/12 -> 0 | AP26: =SUM(AD26:AO26) -> 0
A27: =Assumptions!A29 -> Telephone | B27: =Assumptions!$B29/12 -> 0 | C27: =Assumptions!$B29/12 -> 0 | D27: =Assumptions!$B29/12 -> 0 | E27: =Assumptions!$B29/12 -> 0 | F27: =Assumptions!$B29/12 -> 0 | G27: =Assumptions!$B29/12 -> 0 | H27: =Assumptions!$B29/12 -> 0 | I27: =Assumptions!$B29/12 -> 0 | ... M27: =Assumptions!$B29/12 -> 0 | N27: =SUM(B27:M27) -> 0 | P27: =Assumptions!$C29/12 -> 0 | Q27: =Assumptions!$C29/12 -> 0 | R27: =Assumptions!$C29/12 -> 0 | S27: =Assumptions!$C29/12 -> 0 | T27: =Assumptions!$C29/12 -> 0 | U27: =Assumptions!$C29/12 -> 0 | V27: =Assumptions!$C29/12 -> 0 | W27: =Assumptions!$C29/12 -> 0 | ... AA27: =Assumptions!$C29/12 -> 0 | AB27: =SUM(P27:AA27) -> 0 | AD27: =Assumptions!$D29/12 -> 0 | AE27: =Assumptions!$D29/12 -> 0 | AF27: =Assumptions!$D29/12 -> 0 | AG27: =Assumptions!$D29/12 -> 0 | AH27: =Assumptions!$D29/12 -> 0 | AI27: =Assumptions!$D29/12 -> 0 | AJ27: =Assumptions!$D29/12 -> 0 | AK27: =Assumptions!$D29/12 -> 0 | ... AO27: =Assumptions!$D29/12 -> 0 | AP27: =SUM(AD27:AO27) -> 0
A28: Fund raising costs | B28: =Assumptions!$B41*Cashflow!B7 -> 7500 | C28: =Assumptions!$B41*Cashflow!C7 -> 0 | D28: =Assumptions!$B41*Cashflow!D7 -> 0 | E28: =Assumptions!$B41*Cashflow!E7 -> 0 | F28: =Assumptions!$B41*Cashflow!F7 -> 0 | G28: =Assumptions!$B41*Cashflow!G7 -> 0 | H28: =Assumptions!$B41*Cashflow!H7 -> 0 | I28: =Assumptions!$B41*Cashflow!I7 -> 0 | ... M28: =Assumptions!$B41*Cashflow!M7 -> 0 | N28: =SUM(B28:M28) -> 7500 | P28: =Assumptions!$B41*Cashflow!P7 -> 0 | Q28: =Assumptions!$B41*Cashflow!Q7 -> 0 | R28: =Assumptions!$B41*Cashflow!R7 -> 0 | S28: =Assumptions!$B41*Cashflow!S7 -> 0 | T28: =Assumptions!$B41*Cashflow!T7 -> 0 | U28: =Assumptions!$B41*Cashflow!U7 -> 0 | V28: =Assumptions!$B41*Cashflow!V7 -> 0 | W28: =Assumptions!$B41*Cashflow!W7 -> 0 | ... AP28: =Assumptions!$B41*Cashflow!AP7 -> 0
A29: Contingency | B29: =Assumptions!$B54/12 -> 0 | C29: =Assumptions!$B54/12 -> 0 | D29: =Assumptions!$B54/12 -> 0 | E29: =Assumptions!$B54/12 -> 0 | F29: =Assumptions!$B54/12 -> 0 | G29: =Assumptions!$B54/12 -> 0 | H29: =Assumptions!$B54/12 -> 0 | I29: =Assumptions!$B54/12 -> 0 | ... M29: =Assumptions!$B54/12 -> 0 | N29: =SUM(B29:M29) -> 0 | P29: =Assumptions!$C54/12 -> 833.33333 | Q29: =Assumptions!$C54/12 -> 833.33333 | R29: =Assumptions!$C54/12 -> 833.33333 | S29: =Assumptions!$C54/12 -> 833.33333 | T29: =Assumptions!$C54/12 -> 833.33333 | U29: =Assumptions!$C54/12 -> 833.33333 | V29: =Assumptions!$C54/12 -> 833.33333 | W29: =Assumptions!$C54/12 -> 833.33333 | ... AA29: =Assumptions!$C54/12 -> 833.33333 | AB29: =SUM(P29:AA29) -> 10000 | AD29: =Assumptions!$D54/12 -> 833.33333 | AE29: =Assumptions!$D54/12 -> 833.33333 | AF29: =Assumptions!$D54/12 -> 833.33333 | AG29: =Assumptions!$D54/12 -> 833.33333 | AH29: =Assumptions!$D54/12 -> 833.33333 | AI29: =Assumptions!$D54/12 -> 833.33333 | AJ29: =Assumptions!$D54/12 -> 833.33333 | AK29: =Assumptions!$D54/12 -> 833.33333 | ... AO29: =Assumptions!$D54/12 -> 833.33333 | AP29: =SUM(AD29:AO29) -> 10000
A30: Depreciation | B30: =Assumptions!B59*0.25/12 -> 0 | C30: =Assumptions!C59*0.25/12 -> 0 | D30: =Assumptions!D59*0.25/12 -> 0 | E30: =Assumptions!E59*0.25/12 -> 0 | F30: =Assumptions!F59*0.25/12 -> 0 | G30: =Assumptions!G59*0.25/12 -> 0 | H30: =Assumptions!H59*0.25/12 -> 0 | I30: =Assumptions!I59*0.25/12 -> 0 | ... M30: =Assumptions!M59*0.25/12 -> 0 | N30: =SUM(B30:M30) -> 0 | P30: =Assumptions!B63*0.25/12 -> 0 | Q30: =Assumptions!C63*0.25/12 -> 0 | R30: =Assumptions!D63*0.25/12 -> 0 | S30: =Assumptions!E63*0.25/12 -> 0 | T30: =Assumptions!F63*0.25/12 -> 0 | U30: =Assumptions!G63*0.25/12 -> 0 | V30: =Assumptions!H63*0.25/12 -> 0 | W30: =Assumptions!I63*0.25/12 -> 0 | ... AA30: =Assumptions!M63*0.25/12 -> 0 | AB30: =SUM(P30:AA30) -> 0 | AD30: =Assumptions!B67*0.25/12 -> 0 | AE30: =Assumptions!C67*0.25/12 -> 0 | AF30: =Assumptions!D67*0.25/12 -> 0 | AG30: =Assumptions!E67*0.25/12 -> 0 | AH30: =Assumptions!F67*0.25/12 -> 0 | AI30: =Assumptions!G67*0.25/12 -> 0 | AJ30: =Assumptions!H67*0.25/12 -> 0 | AK30: =Assumptions!I67*0.25/12 -> 0 | ... AO30: =Assumptions!M67*0.25/12 -> 0 | AP30: =SUM(AD30:AO30) -> 0
A32: Total | B32: =SUM(B17:B31) -> 20416.667 | C32: =SUM(C17:C31) -> 12916.667 | D32: =SUM(D17:D31) -> 12916.667 | E32: =SUM(E17:E31) -> 12916.667 | F32: =SUM(F17:F31) -> 12916.667 | G32: =SUM(G17:G31) -> 12916.667 | H32: =SUM(H17:H31) -> 12916.667 | I32: =SUM(I17:I31) -> 12916.667 | ... M32: =SUM(M17:M31) -> 12916.667 | N32: =SUM(B32:M32) -> 162500 | P32: =SUM(P17:P31) -> 13250 | Q32: =SUM(Q17:Q31) -> 11250 | R32: =SUM(R17:R31) -> 11250 | S32: =SUM(S17:S31) -> 13250 | T32: =SUM(T17:T31) -> 12250 | U32: =SUM(U17:U31) -> 12250 | V32: =SUM(V17:V31) -> 13250 | W32: =SUM(W17:W31) -> 12250 | ... AA32: =SUM(AA17:AA31) -> 12250 | AB32: =SUM(P32:AA32) -> 148000 | AD32: =SUM(AD17:AD31) -> 17333.333 | AE32: =SUM(AE17:AE31) -> 15333.333 | AF32: =SUM(AF17:AF31) -> 15333.333 | AG32: =SUM(AG17:AG31) -> 15333.333 | AH32: =SUM(AH17:AH31) -> 17333.333 | AI32: =SUM(AI17:AI31) -> 15333.333 | AJ32: =SUM(AJ17:AJ31) -> 15333.333 | AK32: =SUM(AK17:AK31) -> 15333.333 | ... AO32: =SUM(AO17:AO31) -> 15333.333 | AP32: =SUM(AD32:AO32) -> 190000
A35: Profit (loss) before tax | B35: =B13-B32 -> -20416.667 | C35: =C13-C32 -> -12916.667 | D35: =D13-D32 -> -12916.667 | E35: =E13-E32 -> -12916.667 | F35: =F13-F32 -> -12916.667 | G35: =G13-G32 -> -12916.667 | H35: =H13-H32 -> -12916.667 | I35: =I13-I32 -> -12916.667 | ... N35: =N13-N32 -> -148854.56 | P35: =P13-P32 -> -5974.4915 | Q35: =Q13-Q32 -> -1978.4351 | R35: =R13-R32 -> 540.87682 | S35: =S13-S32 -> 1705.8162 | T35: =T13-T32 -> 6658.6227 | U35: =U13-U32 -> 11559.475 | V35: =V13-V32 -> 16580.991 | W35: =W13-W32 -> 24897.669 | ... AB35: =AB13-AB32 -> 257215.76 | AD35: =AD13-AD32 -> 79440.92 | AE35: =AE13-AE32 -> 97532.353 | AF35: =AF13-AF32 -> 114322.45 | AG35: =AG13-AG32 -> 131312.17 | AH35: =AH13-AH32 -> 145978.44 | AI35: =AI13-AI32 -> 163836.94 | AJ35: =AJ13-AJ32 -> 178495.42 | AK35: =AK13-AK32 -> 191685.88 | ... AP35: =AP13-AP32 -> 1967391.5
A37: Tax | M37: 0 | N37: =SUM(B37:M37) -> 0 | AA37: =IF((AB35+N35)*0.2>0,(AB35+N35)*0.19,0) -> 20588.627 | AB37: =SUM(P37:AA37) -> 20588.627 | AO37: =IF((N35+AB35+AP35)*0.2>0,(N35+AB35+AP35)*-0.19,0) -> -394393.01 | AP37: =SUM(AD37:AO37) -> -394393.01
A39: Retained profit | B39: =SUM(B35:B38) -> -20416.667 | C39: =SUM(C35:C38) -> -12916.667 | D39: =SUM(D35:D38) -> -12916.667 | E39: =SUM(E35:E38) -> -12916.667 | F39: =SUM(F35:F38) -> -12916.667 | G39: =SUM(G35:G38) -> -12916.667 | H39: =SUM(H35:H38) -> -12916.667 | I39: =SUM(I35:I38) -> -12916.667 | ... N39: =SUM(N35:N38) -> -148854.56 | P39: =SUM(P35:P38) -> -5974.4915 | Q39: =SUM(Q35:Q38) -> -1978.4351 | R39: =SUM(R35:R38) -> 540.87682 | S39: =SUM(S35:S38) -> 1705.8162 | T39: =SUM(T35:T38) -> 6658.6227 | U39: =SUM(U35:U38) -> 11559.475 | V39: =SUM(V35:V38) -> 16580.991 | W39: =SUM(W35:W38) -> 24897.669 | ... AB39: =SUM(AB35:AB38) -> 277804.38 | AD39: =SUM(AD35:AD38) -> 79440.92 | AE39: =SUM(AE35:AE38) -> 97532.353 | AF39: =SUM(AF35:AF38) -> 114322.45 | AG39: =SUM(AG35:AG38) -> 131312.17 | AH39: =SUM(AH35:AH38) -> 145978.44 | AI39: =SUM(AI35:AI38) -> 163836.94 | AJ39: =SUM(AJ35:AJ38) -> 178495.42 | AK39: =SUM(AK35:AK38) -> 191685.88 | ... AP39: =SUM(AP35:AP38) -> 1572998.5

Sheet Cashflow
A1: =Assumptions!B1 -> CONKR.
A2: Cashlow forecast
B4: Month 1 | C4: Month 2 | D4: Month 3 | E4: Month 4 | F4: Month 5 | G4: Month 6 | H4: Month 7 | I4: Month 8 | J4: Month 9 | K4: Month 10 | L4: Month 11 | M4: Month 12 | N4: TOTAL | P4: Month 13 | Q4: Month 14 | R4: Month 15 | S4: Month 16 | T4: Month 17 | U4: Month 18 | V4: Month 19 | W4: Month 20 | X4: Month 21 | Y4: Month 22 | Z4: Month 23 | AA4: Month 24 | AB4: Total | AD4: Month 25 | AE4: Month 26 | AF4: Month 27 | AG4: Month 28 | AH4: Month 29 | AI4: Month 30 | AJ4: Month 31 | AK4: Month 32 | AL4: Month 33 | AM4: Month 34 | AN4: Month 35 | AO4: Month 36 | AP4: Total
A5: Income
A6: Founder | B6: =Assumptions!B32 -> 15000 | C6: =Assumptions!C32 | D6: =Assumptions!D32 | E6: =Assumptions!E32 | F6: =Assumptions!F32 | G6: =Assumptions!G32 | H6: =Assumptions!H32 | I6: =Assumptions!I32 | ... M6: =Assumptions!M32 | N6: =SUM(B6:M6) -> 15000 | P6: =Assumptions!B35 | Q6: =Assumptions!C35 | R6: =Assumptions!D35 | S6: =Assumptions!E35 | T6: =Assumptions!F35 | U6: =Assumptions!G35 | V6: =Assumptions!H35 | W6: =Assumptions!I35 | ... AA6: =Assumptions!M35 | AB6: =SUM(P6:AA6) -> 0 | AD6: =Assumptions!B38 | AE6: =Assumptions!C38 | AF6: =Assumptions!D38 | AG6: =Assumptions!E38 | AH6: =Assumptions!F38 | AI6: =Assumptions!G38 | AJ6: =Assumptions!H38 | AK6: =Assumptions!I38 | ... AO6: =Assumptions!M38 | AP6: =SUM(AD6:AO6) -> 0
A7: Investment | B7: =Assumptions!B33 -> 150000 | C7: =Assumptions!C33 | D7: =Assumptions!D33 | E7: =Assumptions!E33 | F7: =Assumptions!F33 | G7: =Assumptions!G33 -> 0 | H7: =Assumptions!H33 | I7: =Assumptions!I33 | ... M7: =Assumptions!M33 | N7: =SUM(B7:M7) -> 150000 | P7: =Assumptions!B36 -> 0 | Q7: =Assumptions!C36 | R7: =Assumptions!D36 | S7: =Assumptions!E36 | T7: =Assumptions!F36 | U7: =Assumptions!G36 | V7: =Assumptions!H36 | W7: =Assumptions!I36 | ... AA7: =Assumptions!M36 | AB7: =SUM(P7:AA7) -> 0 | AE7: =Assumptions!C39 | AF7: =Assumptions!D39 | AG7: =Assumptions!E39 | AH7: =Assumptions!F39 | AI7: =Assumptions!G39 | AJ7: =Assumptions!H39 | AK7: =Assumptions!I39 | AL7: =Assumptions!J39 | ... AO7: =Assumptions!M39 | AP7: =SUM(AD7:AO7) -> 0
A8: ='P&L'!A6 -> User income | B8: ='P&L'!B6*1.2 -> 0 | C8: ='P&L'!C6*1.2 -> 0 | D8: ='P&L'!D6*1.2 -> 0 | E8: ='P&L'!E6*1.2 -> 0 | F8: ='P&L'!F6*1.2 -> 0 | G8: ='P&L'!G6*1.2 -> 0 | H8: ='P&L'!H6*1.2 -> 0 | I8: ='P&L'!I6*1.2 -> 0 | ... M8: ='P&L'!M6*1.2 -> 6908.9273 | N8: =SUM(B8:M8) -> 16539.923 | P8: ='P&L'!P6*1.2 -> 8818.7982 | Q8: ='P&L'!Q6*1.2 -> 11238.261 | R8: ='P&L'!R6*1.2 -> 14291.972 | S8: ='P&L'!S6*1.2 -> 18128.262 | T8: ='P&L'!T6*1.2 -> 22919.543 | U8: ='P&L'!U6*1.2 -> 28859.97 | V8: ='P&L'!V6*1.2 -> 36158.777 | W8: ='P&L'!W6*1.2 -> 45027.477 | ... AA8: ='P&L'!AA6*1.2 -> 99151.002 | AB8: =SUM(P8:AA8) -> 491170.61 | AD8: ='P&L'!AD6*1.2 -> 117302.13 | AE8: ='P&L'!AE6*1.2 -> 136806.89 | AF8: ='P&L'!AF6*1.2 -> 157158.52 | AG8: ='P&L'!AG6*1.2 -> 177752.13 | AH8: ='P&L'!AH6*1.2 -> 197953.67 | AI8: ='P&L'!AI6*1.2 -> 217176.09 | AJ8: ='P&L'!AJ6*1.2 -> 234943.94 | AK8: ='P&L'!AK6*1.2 -> 250932.39 | ... AO8: ='P&L'!AO6*1.2 -> 295720.9 | AP8: =SUM(AD8:AO8) -> 2615020
A9: VAT Recovered | E9: =IF('Bal Sht'!D9>0,'Bal Sht'!D9,0) -> 6250 | H9: =IF('Bal Sht'!G9>0,'Bal Sht'!G9,0) -> 4750 | K9: =IF('Bal Sht'!J9>0,'Bal Sht'!J9,0) -> 4750 | N9: =SUM(B9:L9) -> 15750 | P9: =IF('Bal Sht'!M9>0,'Bal Sht'!M9,0) -> 2020.9128 | S9: =IF('Bal Sht'!R9>0,'Bal Sht'!R9,0) -> 0 | V9: =IF('Bal Sht'!U9>0,'Bal Sht'!U9,0) -> 0 | Y9: =IF('Bal Sht'!X9>0,'Bal Sht'!X9,0) -> 0 | AB9: =SUM(P9:AA9) -> 2020.9128 | AD9: =IF('Bal Sht'!AA9>0,'Bal Sht'!AA9,0) -> 0 | AG9: =IF('Bal Sht'!AF9>0,'Bal Sht'!AF9,0) -> 0 | AJ9: =IF('Bal Sht'!AI9>0,'Bal Sht'!AI9,0) -> 0 | AM9: =IF('Bal Sht'!AL9>0,'Bal Sht'!AL9,0) -> 0
A11: Total | B11: =SUM(B6:B9) -> 165000 | C11: =SUM(C6:C9) -> 0 | D11: =SUM(D6:D9) -> 0 | E11: =SUM(E6:E9) -> 6250 | F11: =SUM(F6:F9) -> 0 | G11: =SUM(G6:G9) -> 0 | H11: =SUM(H6:H9) -> 4750 | I11: =SUM(I6:I9) -> 0 | ... M11: =SUM(M6:M9) -> 6908.9273 | N11: =SUM(B11:M11) -> 197289.92 | P11: =SUM(P6:P9) -> 10839.711 | Q11: =SUM(Q6:Q9) -> 11238.261 | R11: =SUM(R6:R9) -> 14291.972 | S11: =SUM(S6:S9) -> 18128.262 | T11: =SUM(T6:T9) -> 22919.543 | U11: =SUM(U6:U9) -> 28859.97 | V11: =SUM(V6:V9) -> 36158.777 | W11: =SUM(W6:W9) -> 45027.477 | ... AA11: =SUM(AA6:AA9) -> 99151.002 | AB11: =SUM(P11:AA11) -> 493191.53 | AD11: =SUM(AD6:AD9) -> 117302.13 | AE11: =SUM(AE6:AE9) -> 136806.89 | AF11: =SUM(AF6:AF9) -> 157158.52 | AG11: =SUM(AG6:AG9) -> 177752.13 | AH11: =SUM(AH6:AH9) -> 197953.67 | AI11: =SUM(AI6:AI9) -> 217176.09 | AJ11: =SUM(AJ6:AJ9) -> 234943.94 | AK11: =SUM(AK6:AK9) -> 250932.39 | ... AO11: =SUM(AO6:AO9) -> 295720.9 | AP11: =SUM(AD11:AO11) -> 2615020
A13: Expenses
A14: ='P&L'!A11 -> Direct Selling costs | B14: ='P&L'!B11*1.2 -> 0 | C14: ='P&L'!C11*1.2 -> 0 | D14: ='P&L'!D11*1.2 -> 0 | E14: ='P&L'!E11*1.2 -> 0 | F14: ='P&L'!F11*1.2 -> 0 | G14: ='P&L'!G11*1.2 -> 0 | H14: ='P&L'!H11*1.2 -> 0 | I14: ='P&L'!I11*1.2 -> 0 | ... N14: ='P&L'!N11*1.2 -> 165.39923 | P14: ='P&L'!P11*1.2 -> 88.187982 | Q14: ='P&L'!Q11*1.2 -> 112.38261 | R14: ='P&L'!R11*1.2 -> 142.91972 | S14: ='P&L'!S11*1.2 -> 181.28262 | T14: ='P&L'!T11*1.2 -> 229.19543 | U14: ='P&L'!U11*1.2 -> 288.5997 | V14: ='P&L'!V11*1.2 -> 361.58777 | W14: ='P&L'!W11*1.2 -> 450.27477 | ... AB14: ='P&L'!AB11*1.2 -> 4911.7061 | AD14: ='P&L'!AD11*1.2 -> 1173.0213 | AE14: ='P&L'!AE11*1.2 -> 1368.0689 | AF14: ='P&L'!AF11*1.2 -> 1571.5852 | AG14: ='P&L'!AG11*1.2 -> 1777.5213 | AH14: ='P&L'!AH11*1.2 -> 1979.5367 | AI14: ='P&L'!AI11*1.2 -> 2171.7609 | AJ14: ='P&L'!AJ11*1.2 -> 2349.4394 | AK14: ='P&L'!AK11*1.2 -> 2509.3239 | ... AP14: ='P&L'!AP11*1.2 -> 26150.2
A15: =Assumptions!A20 -> CEO | B15: =Assumptions!$B20/12*0.8 -> 1333.3333 | C15: =Assumptions!$B20/12*0.8 -> 1333.3333 | D15: =Assumptions!$B20/12*0.8 -> 1333.3333 | E15: =Assumptions!$B20/12*0.8 -> 1333.3333 | F15: =Assumptions!$B20/12*0.8 -> 1333.3333 | G15: =Assumptions!$B20/12*0.8 -> 1333.3333 | H15: =Assumptions!$B20/12*0.8 -> 1333.3333 | I15: =Assumptions!$B20/12*0.8 -> 1333.3333 | ... M15: =Assumptions!$B20/12*0.8 -> 1333.3333 | N15: =SUM(B15:M15) -> 16000 | P15: =(Assumptions!$C20/12)*0.8 -> 1666.6667 | Q15: =(Assumptions!$C20/12)*0.8 -> 1666.6667 | R15: =(Assumptions!$C20/12)*0.8 -> 1666.6667 | S15: =(Assumptions!$C20/12)*0.8 -> 1666.6667 | T15: =(Assumptions!$C20/12)*0.8 -> 1666.6667 | U15: =(Assumptions!$C20/12)*0.8 -> 1666.6667 | V15: =(Assumptions!$C20/12)*0.8 -> 1666.6667 | W15: =(Assumptions!$C20/12)*0.8 -> 1666.6667 | ... AA15: =(Assumptions!$C20/12)*0.8 -> 1666.6667 | AB15: =SUM(P15:AA15) -> 20000 | AD15: =(Assumptions!$D20/12)*0.8 -> 2666.6667 | AE15: =(Assumptions!$D20/12)*0.8 -> 2666.6667 | AF15: =(Assumptions!$D20/12)*0.8 -> 2666.6667 | AG15: =(Assumptions!$D20/12)*0.8 -> 2666.6667 | AH15: =(Assumptions!$D20/12)*0.8 -> 2666.6667 | AI15: =(Assumptions!$D20/12)*0.8 -> 2666.6667 | AJ15: =(Assumptions!$D20/12)*0.8 -> 2666.6667 | AK15: =(Assumptions!$D20/12)*0.8 -> 2666.6667 | ... AO15: =(Assumptions!$D20/12)*0.8 -> 2666.6667 | AP15: =SUM(AD15:AO15) -> 32000
A16: =Assumptions!A21 -> Administration | B16: =Assumptions!$B21/12*0.8 -> 0 | C16: =Assumptions!$B21/12*0.8 -> 0 | D16: =Assumptions!$B21/12*0.8 -> 0 | E16: =Assumptions!$B21/12*0.8 -> 0 | F16: =Assumptions!$B21/12*0.8 -> 0 | G16: =Assumptions!$B21/12*0.8 -> 0 | H16: =Assumptions!$B21/12*0.8 -> 0 | I16: =Assumptions!$B21/12*0.8 -> 0 | ... M16: =Assumptions!$B21/12*0.8 -> 0 | N16: =SUM(B16:M16) -> 0 | P16: =(Assumptions!$C21/12)*0.8 -> 333.33333 | Q16: =(Assumptions!$C21/12)*0.8 -> 333.33333 | R16: =(Assumptions!$C21/12)*0.8 -> 333.33333 | S16: =(Assumptions!$C21/12)*0.8 -> 333.33333 | T16: =(Assumptions!$C21/12)*0.8 -> 333.33333 | U16: =(Assumptions!$C21/12)*0.8 -> 333.33333 | V16: =(Assumptions!$C21/12)*0.8 -> 333.33333 | W16: =(Assumptions!$C21/12)*0.8 -> 333.33333 | ... AA16: =(Assumptions!$C21/12)*0.8 -> 333.33333 | AB16: =SUM(P16:AA16) -> 4000 | AD16: =(Assumptions!$D21/12)*0.8 -> 333.33333 | AE16: =(Assumptions!$D21/12)*0.8 -> 333.33333 | AF16: =(Assumptions!$D21/12)*0.8 -> 333.33333 | AG16: =(Assumptions!$D21/12)*0.8 -> 333.33333 | AH16: =(Assumptions!$D21/12)*0.8 -> 333.33333 | AI16: =(Assumptions!$D21/12)*0.8 -> 333.33333 | AJ16: =(Assumptions!$D21/12)*0.8 -> 333.33333 | AK16: =(Assumptions!$D21/12)*0.8 -> 333.33333 | ... AO16: =(Assumptions!$D21/12)*0.8 -> 333.33333 | AP16: =SUM(AD16:AO16) -> 4000
A17: =Assumptions!A22 -> Other Staff Costs | B17: =Assumptions!$B22/12*0.8 -> 2666.6667 | C17: =Assumptions!$B22/12*0.8 -> 2666.6667 | D17: =Assumptions!$B22/12*0.8 -> 2666.6667 | E17: =Assumptions!$B22/12*0.8 -> 2666.6667 | F17: =Assumptions!$B22/12*0.8 -> 2666.6667 | G17: =Assumptions!$B22/12*0.8 -> 2666.6667 | H17: =Assumptions!$B22/12*0.8 -> 2666.6667 | I17: =Assumptions!$B22/12*0.8 -> 2666.6667 | ... M17: =Assumptions!$B22/12*0.8 -> 2666.6667 | N17: =SUM(B17:M17) -> 32000 | P17: =(Assumptions!$C22/12)*0.8 -> 3333.3333 | Q17: =(Assumptions!$C22/12)*0.8 -> 3333.3333 | R17: =(Assumptions!$C22/12)*0.8 -> 3333.3333 | S17: =(Assumptions!$C22/12)*0.8 -> 3333.3333 | T17: =(Assumptions!$C22/12)*0.8 -> 3333.3333 | U17: =(Assumptions!$C22/12)*0.8 -> 3333.3333 | V17: =(Assumptions!$C22/12)*0.8 -> 3333.3333 | W17: =(Assumptions!$C22/12)*0.8 -> 3333.3333 | ... AA17: =(Assumptions!$C22/12)*0.8 -> 3333.3333 | AB17: =SUM(P17:AA17) -> 40000 | AD17: =(Assumptions!$D22/12)*0.8 -> 4000 | AE17: =(Assumptions!$D22/12)*0.8 -> 4000 | AF17: =(Assumptions!$D22/12)*0.8 -> 4000 | AG17: =(Assumptions!$D22/12)*0.8 -> 4000 | AH17: =(Assumptions!$D22/12)*0.8 -> 4000 | AI17: =(Assumptions!$D22/12)*0.8 -> 4000 | AJ17: =(Assumptions!$D22/12)*0.8 -> 4000 | AK17: =(Assumptions!$D22/12)*0.8 -> 4000 | ... AO17: =(Assumptions!$D22/12)*0.8 -> 4000 | AP17: =SUM(AD17:AO17) -> 48000
A18: =Assumptions!A43 -> Development Expenditure | B18: ='P&L'!B20*1.2 -> 6000 | C18: ='P&L'!C20*1.2 -> 6000 | D18: ='P&L'!D20*1.2 -> 6000 | E18: ='P&L'!E20*1.2 -> 6000 | F18: ='P&L'!F20*1.2 -> 6000 | G18: ='P&L'!G20*1.2 -> 6000 | H18: ='P&L'!H20*1.2 -> 6000 | I18: ='P&L'!I20*1.2 -> 6000 | ... M18: ='P&L'!M20*1.2 -> 6000 | N18: =SUM(B18:M18) -> 72000 | P18: ='P&L'!P20*1.2 -> 2400 | Q18: ='P&L'!Q20*1.2 -> 0 | R18: ='P&L'!R20*1.2 -> 0 | S18: ='P&L'!S20*1.2 -> 2400 | T18: ='P&L'!T20*1.2 -> 1200 | U18: ='P&L'!U20*1.2 -> 1200 | V18: ='P&L'!V20*1.2 -> 2400 | W18: ='P&L'!W20*1.2 -> 1200 | ... AA18: ='P&L'!AA20*1.2 -> 1200 | AB18: =SUM(P18:AA18) -> 15600 | AD18: ='P&L'!AD20*1.2 -> 4800 | AE18: ='P&L'!AE20*1.2 -> 2400 | AF18: ='P&L'!AF20*1.2 -> 2400 | AG18: ='P&L'!AG20*1.2 -> 2400 | AH18: ='P&L'!AH20*1.2 -> 4800 | AI18: ='P&L'!AI20*1.2 -> 2400 | AJ18: ='P&L'!AJ20*1.2 -> 2400 | AK18: ='P&L'!AK20*1.2 -> 2400 | ... AO18: ='P&L'!AO20*1.2 -> 2400 | AP18: =SUM(AD18:AO18) -> 36000
A19: =Assumptions!A23 -> Motor & travel expenses | B19: ='P&L'!B21*1.2 -> 0 | C19: ='P&L'!C21*1.2 -> 0 | D19: ='P&L'!D21*1.2 -> 0 | E19: ='P&L'!E21*1.2 -> 0 | F19: ='P&L'!F21*1.2 -> 0 | G19: ='P&L'!G21*1.2 -> 0 | H19: ='P&L'!H21*1.2 -> 0 | I19: ='P&L'!I21*1.2 -> 0 | ... M19: ='P&L'!M21*1.2 -> 0 | N19: =SUM(B19:M19) -> 0 | P19: ='P&L'!P21*1.2 -> 0 | Q19: ='P&L'!Q21*1.2 -> 0 | R19: ='P&L'!R21*1.2 -> 0 | S19: ='P&L'!S21*1.2 -> 0 | T19: ='P&L'!T21*1.2 -> 0 | U19: ='P&L'!U21*1.2 -> 0 | V19: ='P&L'!V21*1.2 -> 0 | W19: ='P&L'!W21*1.2 -> 0 | ... AA19: ='P&L'!AA21*1.2 -> 0 | AB19: =SUM(P19:AA19) -> 0 | AD19: ='P&L'!AD21*1.2 -> 0 | AE19: ='P&L'!AE21*1.2 -> 0 | AF19: ='P&L'!AF21*1.2 -> 0 | AG19: ='P&L'!AG21*1.2 -> 0 | AH19: ='P&L'!AH21*1.2 -> 0 | AI19: ='P&L'!AI21*1.2 -> 0 | AJ19: ='P&L'!AJ21*1.2 -> 0 | AK19: ='P&L'!AK21*1.2 -> 0 | ... AO19: ='P&L'!AO21*1.2 -> 0 | AP19: =SUM(AD19:AO19) -> 0
A20: =Assumptions!A24 -> Materials/Resources | B20: ='P&L'!B22*1.2 -> 0 | C20: ='P&L'!C22*1.2 -> 0 | D20: ='P&L'!D22*1.2 -> 0 | E20: ='P&L'!E22*1.2 -> 0 | F20: ='P&L'!F22*1.2 -> 0 | G20: ='P&L'!G22*1.2 -> 0 | H20: ='P&L'!H22*1.2 -> 0 | I20: ='P&L'!I22*1.2 -> 0 | ... M20: ='P&L'!M22*1.2 -> 0 | N20: =SUM(B20:M20) -> 0 | P20: ='P&L'!P22*1.2 -> 0 | Q20: ='P&L'!Q22*1.2 -> 0 | R20: ='P&L'!R22*1.2 -> 0 | S20: ='P&L'!S22*1.2 -> 0 | T20: ='P&L'!T22*1.2 -> 0 | U20: ='P&L'!U22*1.2 -> 0 | V20: ='P&L'!V22*1.2 -> 0 | W20: ='P&L'!W22*1.2 -> 0 | ... AA20: ='P&L'!AA22*1.2 -> 0 | AB20: =SUM(P20:AA20) -> 0 | AD20: ='P&L'!AD22*1.2 -> 0 | AE20: ='P&L'!AE22*1.2 -> 0 | AF20: ='P&L'!AF22*1.2 -> 0 | AG20: ='P&L'!AG22*1.2 -> 0 | AH20: ='P&L'!AH22*1.2 -> 0 | AI20: ='P&L'!AI22*1.2 -> 0 | AJ20: ='P&L'!AJ22*1.2 -> 0 | AK20: ='P&L'!AK22*1.2 -> 0 | ... AO20: ='P&L'!AO22*1.2 -> 0 | AP20: =SUM(AD20:AO20) -> 0
A21: =Assumptions!A25 -> Marketing | B21: ='P&L'!B23*1.2 -> 2000 | C21: ='P&L'!C23*1.2 -> 2000 | D21: ='P&L'!D23*1.2 -> 2000 | E21: ='P&L'!E23*1.2 -> 2000 | F21: ='P&L'!F23*1.2 -> 2000 | G21: ='P&L'!G23*1.2 -> 2000 | H21: ='P&L'!H23*1.2 -> 2000 | I21: ='P&L'!I23*1.2 -> 2000 | ... M21: ='P&L'!M23*1.2 -> 2000 | N21: =SUM(B21:M21) -> 24000 | P21: ='P&L'!P23*1.2 -> 3000 | Q21: ='P&L'!Q23*1.2 -> 3000 | R21: ='P&L'!R23*1.2 -> 3000 | S21: ='P&L'!S23*1.2 -> 3000 | T21: ='P&L'!T23*1.2 -> 3000 | U21: ='P&L'!U23*1.2 -> 3000 | V21: ='P&L'!V23*1.2 -> 3000 | W21: ='P&L'!W23*1.2 -> 3000 | ... AA21: ='P&L'!AA23*1.2 -> 3000 | AB21: =SUM(P21:AA21) -> 36000 | AD21: ='P&L'!AD23*1.2 -> 3000 | AE21: ='P&L'!AE23*1.2 -> 3000 | AF21: ='P&L'!AF23*1.2 -> 3000 | AG21: ='P&L'!AG23*1.2 -> 3000 | AH21: ='P&L'!AH23*1.2 -> 3000 | AI21: ='P&L'!AI23*1.2 -> 3000 | AJ21: ='P&L'!AJ23*1.2 -> 3000 | AK21: ='P&L'!AK23*1.2 -> 3000 | ... AO21: ='P&L'!AO23*1.2 -> 3000 | AP21: =SUM(AD21:AO21) -> 36000
A22: =Assumptions!A26 -> Insurance | B22: ='P&L'!B24*1.2 -> 1400 | C22: ='P&L'!C24*1.2 -> 1400 | D22: ='P&L'!D24*1.2 -> 1400 | E22: ='P&L'!E24*1.2 -> 1400 | F22: ='P&L'!F24*1.2 -> 1400 | G22: ='P&L'!G24*1.2 -> 1400 | H22: ='P&L'!H24*1.2 -> 1400 | I22: ='P&L'!I24*1.2 -> 1400 | ... M22: ='P&L'!M24*1.2 -> 1400 | N22: =SUM(B22:M22) -> 16800 | P22: ='P&L'!P24*1.2 -> 1400 | Q22: ='P&L'!Q24*1.2 -> 1400 | R22: ='P&L'!R24*1.2 -> 1400 | S22: ='P&L'!S24*1.2 -> 1400 | T22: ='P&L'!T24*1.2 -> 1400 | U22: ='P&L'!U24*1.2 -> 1400 | V22: ='P&L'!V24*1.2 -> 1400 | W22: ='P&L'!W24*1.2 -> 1400 | ... AA22: ='P&L'!AA24*1.2 -> 1400 | AB22: =SUM(P22:AA22) -> 16800 | AD22: ='P&L'!AD24*1.2 -> 1400 | AE22: ='P&L'!AE24*1.2 -> 1400 | AF22: ='P&L'!AF24*1.2 -> 1400 | AG22: ='P&L'!AG24*1.2 -> 1400 | AH22: ='P&L'!AH24*1.2 -> 1400 | AI22: ='P&L'!AI24*1.2 -> 1400 | AJ22: ='P&L'!AJ24*1.2 -> 1400 | AK22: ='P&L'!AK24*1.2 -> 1400 | ... AO22: ='P&L'!AO24*1.2 -> 1400 | AP22: =SUM(AD22:AO22) -> 16800
A23: =Assumptions!A27 -> Computer & IT costs | B23: ='P&L'!B25*1.2 -> 100 | C23: ='P&L'!C25*1.2 -> 100 | D23: ='P&L'!D25*1.2 -> 100 | E23: ='P&L'!E25*1.2 -> 100 | F23: ='P&L'!F25*1.2 -> 100 | G23: ='P&L'!G25*1.2 -> 100 | H23: ='P&L'!H25*1.2 -> 100 | I23: ='P&L'!I25*1.2 -> 100 | ... M23: ='P&L'!M25*1.2 -> 100 | N23: =SUM(B23:M23) -> 1200 | P23: ='P&L'!P25*1.2 -> 100 | Q23: ='P&L'!Q25*1.2 -> 100 | R23: ='P&L'!R25*1.2 -> 100 | S23: ='P&L'!S25*1.2 -> 100 | T23: ='P&L'!T25*1.2 -> 100 | U23: ='P&L'!U25*1.2 -> 100 | V23: ='P&L'!V25*1.2 -> 100 | W23: ='P&L'!W25*1.2 -> 100 | ... AA23: ='P&L'!AA25*1.2 -> 100 | AB23: =SUM(P23:AA23) -> 1200 | AD23: ='P&L'!AD25*1.2 -> 100 | AE23: ='P&L'!AE25*1.2 -> 100 | AF23: ='P&L'!AF25*1.2 -> 100 | AG23: ='P&L'!AG25*1.2 -> 100 | AH23: ='P&L'!AH25*1.2 -> 100 | AI23: ='P&L'!AI25*1.2 -> 100 | AJ23: ='P&L'!AJ25*1.2 -> 100 | AK23: ='P&L'!AK25*1.2 -> 100 | ... AO23: ='P&L'!AO25*1.2 -> 100 | AP23: =SUM(AD23:AO23) -> 1200
A24: =Assumptions!A28 -> Office Rent & services | B24: ='P&L'!B26*1.2 -> 0 | C24: ='P&L'!C26*1.2 -> 0 | D24: ='P&L'!D26*1.2 -> 0 | E24: ='P&L'!E26*1.2 -> 0 | F24: ='P&L'!F26*1.2 -> 0 | G24: ='P&L'!G26*1.2 -> 0 | H24: ='P&L'!H26*1.2 -> 0 | I24: ='P&L'!I26*1.2 -> 0 | ... M24: ='P&L'!M26*1.2 -> 0 | N24: =SUM(B24:M24) -> 0 | P24: ='P&L'!P26*1.2 -> 0 | Q24: ='P&L'!Q26*1.2 -> 0 | R24: ='P&L'!R26*1.2 -> 0 | S24: ='P&L'!S26*1.2 -> 0 | T24: ='P&L'!T26*1.2 -> 0 | U24: ='P&L'!U26*1.2 -> 0 | V24: ='P&L'!V26*1.2 -> 0 | W24: ='P&L'!W26*1.2 -> 0 | ... AA24: ='P&L'!AA26*1.2 -> 0 | AB24: =SUM(P24:AA24) -> 0 | AD24: ='P&L'!AD26*1.2 -> 0 | AE24: ='P&L'!AE26*1.2 -> 0 | AF24: ='P&L'!AF26*1.2 -> 0 | AG24: ='P&L'!AG26*1.2 -> 0 | AH24: ='P&L'!AH26*1.2 -> 0 | AI24: ='P&L'!AI26*1.2 -> 0 | AJ24: ='P&L'!AJ26*1.2 -> 0 | AK24: ='P&L'!AK26*1.2 -> 0 | ... AO24: ='P&L'!AO26*1.2 -> 0 | AP24: =SUM(AD24:AO24) -> 0
A25: =Assumptions!A29 -> Telephone | B25: ='P&L'!B27*1.2 -> 0 | C25: ='P&L'!C27*1.2 -> 0 | D25: ='P&L'!D27*1.2 -> 0 | E25: ='P&L'!E27*1.2 -> 0 | F25: ='P&L'!F27*1.2 -> 0 | G25: ='P&L'!G27*1.2 -> 0 | H25: ='P&L'!H27*1.2 -> 0 | I25: ='P&L'!I27*1.2 -> 0 | ... M25: ='P&L'!M27*1.2 -> 0 | N25: =SUM(B25:M25) -> 0 | P25: ='P&L'!P27*1.2 -> 0 | Q25: ='P&L'!Q27*1.2 -> 0 | R25: ='P&L'!R27*1.2 -> 0 | S25: ='P&L'!S27*1.2 -> 0 | T25: ='P&L'!T27*1.2 -> 0 | U25: ='P&L'!U27*1.2 -> 0 | V25: ='P&L'!V27*1.2 -> 0 | W25: ='P&L'!W27*1.2 -> 0 | ... AA25: ='P&L'!AA27*1.2 -> 0 | AB25: =SUM(P25:AA25) -> 0 | AD25: ='P&L'!AD27*1.2 -> 0 | AE25: ='P&L'!AE27*1.2 -> 0 | AF25: ='P&L'!AF27*1.2 -> 0 | AG25: ='P&L'!AG27*1.2 -> 0 | AH25: ='P&L'!AH27*1.2 -> 0 | AI25: ='P&L'!AI27*1.2 -> 0 | AJ25: ='P&L'!AJ27*1.2 -> 0 | AK25: ='P&L'!AK27*1.2 -> 0 | ... AO25: ='P&L'!AO27*1.2 -> 0 | AP25: =SUM(AD25:AO25) -> 0
A26: ='P&L'!A28 -> Fund raising costs | B26: =Assumptions!B33*Assumptions!$B41*1.2 -> 9000 | C26: =Assumptions!C33*Assumptions!$B41*1.2 -> 0 | D26: =Assumptions!D33*Assumptions!$B41*1.2 -> 0 | E26: =Assumptions!E33*Assumptions!$B41*1.2 -> 0 | F26: =Assumptions!F33*Assumptions!$B41*1.2 -> 0 | G26: =Assumptions!G33*Assumptions!$B41*1.2 -> 0 | H26: =Assumptions!H33*Assumptions!$B41*1.2 -> 0 | I26: =Assumptions!I33*Assumptions!$B41*1.2 -> 0 | ... M26: =Assumptions!M33*Assumptions!$B41*1.2 -> 0 | N26: =SUM(B26:M26) -> 9000 | P26: =Assumptions!B36*Assumptions!$B41*1.2 -> 0 | Q26: =Assumptions!C36*Assumptions!$B41*1.2 -> 0 | R26: =Assumptions!D36*Assumptions!$B41*1.2 -> 0 | S26: =Assumptions!E36*Assumptions!$B41*1.2 -> 0 | T26: =Assumptions!F36*Assumptions!$B41*1.2 -> 0 | U26: =Assumptions!G36*Assumptions!$B41*1.2 -> 0 | V26: =Assumptions!H36*Assumptions!$B41*1.2 -> 0 | W26: =Assumptions!I36*Assumptions!$B41*1.2 -> 0 | ... AA26: =Assumptions!M36*Assumptions!$B41*1.2 -> 0 | AB26: =SUM(P26:AA26) -> 0 | AD26: =Assumptions!B39*Assumptions!$B41*1.2 -> 0 | AE26: =Assumptions!C39*Assumptions!$B41*1.2 -> 0 | AF26: =Assumptions!D39*Assumptions!$B41*1.2 -> 0 | AG26: =Assumptions!E39*Assumptions!$B41*1.2 -> 0 | AH26: =Assumptions!F39*Assumptions!$B41*1.2 -> 0 | AI26: =Assumptions!G39*Assumptions!$B41*1.2 -> 0 | AJ26: =Assumptions!H39*Assumptions!$B41*1.2 -> 0 | AK26: =Assumptions!I39*Assumptions!$B41*1.2 -> 0 | ... AO26: =Assumptions!M39*Assumptions!$B41*1.2 -> 0 | AP26: =SUM(AD26:AO26) -> 0
A27: ='P&L'!A29 -> Contingency | B27: ='P&L'!B29*1.2 -> 0 | C27: ='P&L'!C29*1.2 -> 0 | D27: ='P&L'!D29*1.2 -> 0 | E27: ='P&L'!E29*1.2 -> 0 | F27: ='P&L'!F29*1.2 -> 0 | G27: ='P&L'!G29*1.2 -> 0 | H27: ='P&L'!H29*1.2 -> 0 | I27: ='P&L'!I29*1.2 -> 0 | ... M27: ='P&L'!M29*1.2 -> 0 | N27: =SUM(B27:M27) -> 0 | P27: ='P&L'!P29*1.2 -> 1000 | Q27: ='P&L'!Q29*1.2 -> 1000 | R27: ='P&L'!R29*1.2 -> 1000 | S27: ='P&L'!S29*1.2 -> 1000 | T27: ='P&L'!T29*1.2 -> 1000 | U27: ='P&L'!U29*1.2 -> 1000 | V27: ='P&L'!V29*1.2 -> 1000 | W27: ='P&L'!W29*1.2 -> 1000 | ... AA27: ='P&L'!AA29*1.2 -> 1000 | AB27: =SUM(P27:AA27) -> 12000 | AD27: ='P&L'!AD29*1.2 -> 1000 | AE27: ='P&L'!AE29*1.2 -> 1000 | AF27: ='P&L'!AF29*1.2 -> 1000 | AG27: ='P&L'!AG29*1.2 -> 1000 | AH27: ='P&L'!AH29*1.2 -> 1000 | AI27: ='P&L'!AI29*1.2 -> 1000 | AJ27: ='P&L'!AJ29*1.2 -> 1000 | AK27: ='P&L'!AK29*1.2 -> 1000 | ... AO27: ='P&L'!AO29*1.2 -> 1000 | AP27: =SUM(AD27:AO27) -> 12000
A28: Captal expenditure | B28: =Assumptions!B58*1.2 -> 0 | C28: =Assumptions!C58*1.2 -> 0 | D28: =Assumptions!D58*1.2 -> 0 | E28: =Assumptions!E58*1.2 -> 0 | F28: =Assumptions!F58*1.2 -> 0 | G28: =Assumptions!G58*1.2 -> 0 | H28: =Assumptions!H58*1.2 -> 0 | I28: =Assumptions!I58*1.2 -> 0 | ... M28: =Assumptions!M58*1.2 -> 0 | N28: =SUM(B28:M28) -> 0 | P28: =Assumptions!B62*1.2 -> 0 | Q28: =Assumptions!C62*1.2 -> 0 | R28: =Assumptions!D62*1.2 -> 0 | S28: =Assumptions!E62*1.2 -> 0 | T28: =Assumptions!F62*1.2 -> 0 | U28: =Assumptions!G62*1.2 -> 0 | V28: =Assumptions!H62*1.2 -> 0 | W28: =Assumptions!I62*1.2 -> 0 | ... AA28: =Assumptions!M62*1.2 -> 0 | AB28: =SUM(P28:AA28) -> 0 | AD28: =Assumptions!B66*1.2 -> 0 | AE28: =Assumptions!C66*1.2 -> 0 | AF28: =Assumptions!D66*1.2 -> 0 | AG28: =Assumptions!E66*1.2 -> 0 | AH28: =Assumptions!F66*1.2 -> 0 | AI28: =Assumptions!G66*1.2 -> 0 | AJ28: =Assumptions!H66*1.2 -> 0 | AK28: =Assumptions!I66*1.2 -> 0 | ... AO28: =Assumptions!M66*1.2 -> 0 | AP28: =SUM(AD28:AO28) -> 0
A29: PAYE | C29: =SUM('P&L'!B17:B19)*0.2 -> 1000 | D29: =SUM('P&L'!C17:C19)*0.2 -> 1000 | E29: =SUM('P&L'!D17:D19)*0.2 -> 1000 | F29: =SUM('P&L'!E17:E19)*0.2 -> 1000 | G29: =SUM('P&L'!F17:F19)*0.2 -> 1000 | H29: =SUM('P&L'!G17:G19)*0.2 -> 1000 | I29: =SUM('P&L'!H17:H19)*0.2 -> 1000 | J29: =SUM('P&L'!I17:I19)*0.2 -> 1000 | ... M29: =SUM('P&L'!L17:L19)*0.2 -> 1000 | N29: =SUM(B29:M29) -> 11000 | P29: =-'Bal Sht'!M11 -> 1000 | Q29: =-'Bal Sht'!P11 -> 1333.3333 | R29: =-'Bal Sht'!Q11 -> 1333.3333 | S29: =-'Bal Sht'!R11 -> 1333.3333 | T29: =-'Bal Sht'!S11 -> 1333.3333 | U29: =-'Bal Sht'!T11 -> 1333.3333 | V29: =-'Bal Sht'!U11 -> 1333.3333 | W29: =-'Bal Sht'!V11 -> 1333.3333 | X29: =-'Bal Sht'!W11 -> 1333.3333 | ... AA29: =-'Bal Sht'!Z11 -> 1333.3333 | AB29: =SUM(P29:AA29) -> 15666.667 | AD29: =-'Bal Sht'!AA11 -> 1333.3333 | AE29: =-'Bal Sht'!AD11 -> 1750 | AF29: =-'Bal Sht'!AE11 -> 1750 | AG29: =-'Bal Sht'!AF11 -> 1750 | AH29: =-'Bal Sht'!AG11 -> 1750 | AI29: =-'Bal Sht'!AH11 -> 1750 | AJ29: =-'Bal Sht'!AI11 -> 1750 | AK29: =-'Bal Sht'!AJ11 -> 1750 | AL29: =-'Bal Sht'!AK11 -> 1750 | ... AO29: =-'Bal Sht'!AN11 -> 1750 | AP29: =SUM(AD29:AO29) -> 20583.333
A30: VAT Paid | E30: =-IF('Bal Sht'!D9>0,0,'Bal Sht'!D9) -> 0 | H30: =-IF('Bal Sht'!G9>0,0,'Bal Sht'!G9) -> 0 | K30: =-IF('Bal Sht'!J9>0,0,'Bal Sht'!J9) -> 0 | N30: =SUM(B30:M30) -> 0 | P30: =-IF('Bal Sht'!M9>0,0,'Bal Sht'!M9) -> 0 | S30: =-IF('Bal Sht'!R9>0,0,'Bal Sht'!R9) -> 2517.5901 | V30: =-IF('Bal Sht'!U9>0,0,'Bal Sht'!U9) -> 7984.7829 | Y30: =-IF('Bal Sht'!X9>0,0,'Bal Sht'!X9) -> 19029.53 | AB30: =SUM(P30:AA30) -> 29531.903 | AD30: =-IF('Bal Sht'!AA9>0,0,'Bal Sht'!AA9) -> 37911.249 | AG30: =-IF('Bal Sht'!AF9>0,0,'Bal Sht'!AF9) -> 63509.145 | AJ30: =-IF('Bal Sht'!AI9>0,0,'Bal Sht'!AI9) -> 93475.511 | AM30: =-IF('Bal Sht'!AL9>0,0,'Bal Sht'!AL9) -> 119540.61 | AP30: =SUM(AD30:AO30) -> 314436.52
A31: C Tax | N31: =SUM(B31:M31) -> 0 | AB31: =SUM(P31:AA31) -> 0 | AL31: =-'P&L'!AB37 -> -20588.627 | AP31: =SUM(AD31:AO31) -> -20588.627
A33: Total | B33: =SUM(B14:B32) -> 22500 | C33: =SUM(C14:C32) -> 14500 | D33: =SUM(D14:D32) -> 14500 | E33: =SUM(E14:E32) -> 14500 | F33: =SUM(F14:F32) -> 14500 | G33: =SUM(G14:G32) -> 14500 | H33: =SUM(H14:H32) -> 14500 | I33: =SUM(I14:I32) -> 14500 | ... N33: =SUM(N14:N32) -> 182165.4 | P33: =SUM(P14:P32) -> 14321.521 | Q33: =SUM(Q14:Q32) -> 12279.049 | R33: =SUM(R14:R32) -> 12309.586 | S33: =SUM(S14:S32) -> 17265.539 | T33: =SUM(T14:T32) -> 13595.862 | U33: =SUM(U14:U32) -> 13655.266 | V33: =SUM(V14:V32) -> 22913.037 | W33: =SUM(W14:W32) -> 13816.941 | ... AB33: =SUM(AB14:AB32) -> 195710.28 | AD33: =SUM(AD14:AD32) -> 57717.603 | AE33: =SUM(AE14:AE32) -> 18018.069 | AF33: =SUM(AF14:AF32) -> 18221.585 | AG33: =SUM(AG14:AG32) -> 81936.666 | AH33: =SUM(AH14:AH32) -> 21029.537 | AI33: =SUM(AI14:AI32) -> 18821.761 | AJ33: =SUM(AJ14:AJ32) -> 112474.95 | AK33: =SUM(AK14:AK32) -> 19159.324 | ... AP33: =SUM(AP14:AP32) -> 526581.42
